
Namespace(D_lr=0.0001, base_lr=0.01, batch_size=4, beta=0.3, consistency=1.0, consistency_rampup=40.0, consistency_type='kl', consistency_weight=0.1, deterministic=1, ema_decay=0.99, exp='LA/SSL_DTC_VNet', gamma=0.5, gpu='5', labeled_bs=2, labelnum=16, max_iterations=6000, root_path='/data/sohui/LA_dataset/2018LA_Seg_TrainingSet', seed=1337, with_cons='without_cons')
  0%|                                         | 0/751 [00:00<?, ?it/s]
total 80 samples
  0%|                                         | 0/751 [00:08<?, ?it/s]
Traceback (most recent call last):
  File "/home/sohui/code/DTC/code/SSL_train_la_dtc_VNet.py", line 200, in <module>
    gt_dis = compute_sdf(label_batch[:].cpu(
  File "/home/sohui/code/DTC/code/utils/util.py", line 156, in compute_sdf
    plt.imshow(sdf[:, :], cmap='gray')
  File "/home/sohui/anaconda3/envs/unetr/lib/python3.8/site-packages/matplotlib/pyplot.py", line 2671, in imshow
    __ret = gca().imshow(
  File "/home/sohui/anaconda3/envs/unetr/lib/python3.8/site-packages/matplotlib/__init__.py", line 1589, in inner
    return func(ax, *map(sanitize_sequence, args), **kwargs)
  File "/home/sohui/anaconda3/envs/unetr/lib/python3.8/site-packages/matplotlib/cbook/deprecation.py", line 369, in wrapper
    return func(*args, **kwargs)
  File "/home/sohui/anaconda3/envs/unetr/lib/python3.8/site-packages/matplotlib/cbook/deprecation.py", line 369, in wrapper
    return func(*args, **kwargs)
  File "/home/sohui/anaconda3/envs/unetr/lib/python3.8/site-packages/matplotlib/axes/_axes.py", line 5660, in imshow
    im.set_data(X)
  File "/home/sohui/anaconda3/envs/unetr/lib/python3.8/site-packages/matplotlib/image.py", line 682, in set_data
    raise TypeError("Invalid shape {} for image data"
TypeError: Invalid shape (112, 112, 80) for image data