
Namespace(D_lr=0.0001, base_lr=0.01, batch_size=4, beta=0.3, consistency=1.0, consistency_rampup=40.0, consistency_type='kl', consistency_weight=0.1, deterministic=1, ema_decay=0.99, exp='LA/SSL_DTC_VNet_concat_consis0.2', gamma=0.5, gpu='1', labeled_bs=2, labelnum=16, max_iterations=6000, root_path='/data/sohui/LA_dataset/2018LA_Seg_TrainingSet', seed=1337, with_cons='without_cons')
  0%|                                         | 0/751 [00:00<?, ?it/s]
total 80 samples
  0%|                                         | 0/751 [00:10<?, ?it/s]
Traceback (most recent call last):
  File "/home/sohui/.pycharm_helpers/pydev/pydevd.py", line 1483, in _exec
    pydev_imports.execfile(file, globals, locals)  # execute the script
  File "/home/sohui/.pycharm_helpers/pydev/_pydev_imps/_pydev_execfile.py", line 18, in execfile
    exec(compile(contents+"\n", file, 'exec'), glob, loc)
  File "/home/sohui/code/DTC/code/SSL_train_la_dtc_VNet.py", line 212, in <module>
    loss_BD = losses_2.boundary_loss(outputs_soft[:labeled_bs], gt_sdf)
  File "/home/sohui/code/DTC/code/utils/losses_2.py", line 146, in boundary_loss
    pc = outputs_soft[:,1,...]
IndexError: index 1 is out of bounds for dimension 1 with size 1